<mujoco>
<!-- =================================================
	Copyright 2017 Vikash Kumar
	Model   :: ADROIT MANIPULATION PLATFORM (MuJoCoV2.0)
	Author  :: Vikash Kumar (vikashplus@gmail.com)
	Source  :: https://github.com/vikashplus/Adroit
	License :: Under Apache License, Version 2.0 (the "License"); you may not use this file except in compliance with the License. You may obtain a copy of the License at http://www.apache.org/licenses/LICENSE-2.0 Unless required by applicable law or agreed to in writing, software distributed under the License is distributed on an "AS IS" BASIS, WITHOUT WARRANTIES OR CONDITIONS OF ANY KIND, either express or implied. See the License for the specific language governing permissions and limitations under the License.
	Details :: Manipulator and Manipulation in High Dimensional Spaces. Vikash Kumar, Ph.D. Thesis, CSE, Univ. of Washington. 2016.
			:: With help from Shadow robot company (https://github.com/shadow-robot/sr_common)
====================================================== -©vk©-->

	<include file="resources/assets.xml"/>
	<include file="resources/joint_position_actuation.xml"/> <!-- Joint position servos -->
    
	<asset>
		<texture name="texplane" type="2d" builtin="checker" rgb1=".2 .3 .4" rgb2=".1 0.15 0.2"
			width="512" height="512"/>
		<material name='MatGnd' reflectance='0.5' texture="texplane" texrepeat="2 2" texuniform="true"/>
	</asset>
	<!-- ======= WORLD ======= -->
	<worldbody>
		<light directional='false' diffuse='.8 .8 .8' specular='0.3 0.3 0.3' pos='0 1.0 4.0' dir='0 -1.0 -4'/>
		<geom name="ground" pos="0 0 0" size="0 0 10" material="MatGnd" type="plane" contype="1" conaffinity="1"/>

        <body name="DESK" pos="-.79 .095 .405">
            <geom name="desk" type="box" pos="0 0 0" size="1.14 .535 .405"/>
        </body>

        <body name="TARGET" pos="-1.75 0 .81" childclass="Adroit">
            <freejoint/>
            <geom name="target" type="cylinder" pos="0 0 0.1 + 0.03" size="0.032 0.1"/>
        </body>

        <body name="robot" pos="-2.15 .1 0" childclass="Adroit">
            <geom name="head" type="sphere" pos="-.0079156494140625 -.024686365127563477 1.4261891174316406" size=".1"/>
            <body name="neck" pos="-.008070755004882812 -.02468634605407715 1.8652143859863281"/>
            <body name="uwaist" pos="-.0079156494140625 -.024686365127563477 1.15" >
                <geom name="breast" type="capsule" fromto="0 -0.05 0 0 0.05 0"  size=".07 .1" />
            </body>
            <body name="lwaist" pos="-.0079156494140625 -.024686365127563477 .4227328872680664" >
                <geom name="butt" type="cylinder" fromto="0 0 -.4227328872680664 0 0 .5772671127319336"  size="0.15" />
            </body>
            <body name="right_upper_arm" pos="-.011753921508789062 -.16946983337402344 1.2444410705566407" >
			    <joint name="right_shoulder_1" type="hinge" pos="0 0 0" axis="1 0 0" range="-1.730843 0.02623156"   armature="0.068" frictionloss="0.05" damping="6"/>
			    <joint name="right_shoulder_2" type="hinge" pos="0 0 0" axis="0 1 0" range="-3.14159  1.5708"   armature="0.051" frictionloss="0.05" damping="5"/>
                <geom name="right_uarm1" type="capsule" fromto="0 0 0 0.0018 -0.042 -0.171"  size="0.04 0.16"/>
                <body name="right_lower_arm" pos="0.0024762725830078124 -0.054919137954711914 -0.2279962158203125" >
                    <joint name="right_elbow_1" type="hinge" pos="0 0 0" axis="0 1 0" range="-1.6151277 0.67701322" armature="0.0128" frictionloss="0.05" damping="3"/>
                    <joint name="right_elbow_2" type="hinge" pos="0 0 0" axis="0 0 1" range="-3.14159 3.14159"      armature="0.0128" frictionloss="0.05" damping="1.5"/>
                    <joint name="right_elbow_3" type="hinge" pos="0 0 0" axis="1 0 0" range="-0.67701322 1.6151277" armature="0.0128" frictionloss="0.05" damping="3"/>
                    <geom name="right_larm" type="capsule" fromto="0 0 0 0.00032 0.0000056 -0.17"  size="0.031" />
                    <body name="right_hand" pos="0.0005278778076171875 0.000011949539184570312 -0.20969314575195314">
			            <!-- <joint type="free" limited="false"/> -->
			            <include file="resources/hand.xml"/>
		            </body>
                </body>
            </body>
            <body name="left_upper_arm" pos="-0.0100872802734375 0.16904844284057619 1.24626602172851564" >
                <joint name="left_shoulder_1" type="hinge" pos="0 0 0" axis="1 0 0" range="-0.02623156 1.730843"   armature="0.068" frictionloss="0.05" damping="6"/>
                <joint name="left_shoulder_2" type="hinge" pos="0 0 0" axis="0 1 0" range="-3.14159 1.5708"    armature="0.051" frictionloss="0.05" damping="5"/>
                <geom name="left_uarm1" type="capsule" fromto="0 0 0 0.0018 0.036 -0.171"  size="0.04 0.16" />
                <body name="left_lower_arm" pos="0.00249603271484375 0.048687191009521485 -0.22857582092285156" >
                    <joint name="left_elbow_1" type="hinge" pos="0 0 0" axis="0 1 0" range="-1.6151277 0.67701322" armature="0.0128" frictionloss="0.05" damping="3"/>
                    <joint name="left_elbow_2" type="hinge" pos="0 0 0" axis="0 0 1" range="-3.14159 3.14159"      armature="0.0128" frictionloss="0.05" damping="1.5"/>
                    <joint name="left_elbow_3" type="hinge" pos="0 0 0" axis="1 0 0" range="-1.6151277 0.67701322" armature="0.0128" frictionloss="0.05" damping="3"/>
                    <geom name="left_larm" type="capsule" fromto="0 0 0 0.00034 -0.00009 -0.17"  size="0.031" />
                    <body name="left_hand" pos="0.00054595947265625 -0.00019681930541992187 -0.20955787658691405">
                        <geom name="left_wrist" type="sphere" pos="0 0 0"  size="0.04"/>
		            </body>
                </body>
            </body>
        </body>
	</worldbody>

</mujoco>
